<robot name="full_assembly">
  <link name="Torso_Top_Left">
    <visual>
      <origin xyz="0 0 0" rpy="0 0 0" />
      <geometry>
        <mesh filename="meshes/Torso_Top_Left.stl" />
      </geometry>
      <material name="Torso_Top_Left_material">
        <color rgba="0.97254902 0.52941176 0.0039215686 1" />
      </material>
    </visual>
    <collision>
      <origin xyz="0 0 0" rpy="0 0 0" />
      <geometry>
        <mesh filename="meshes/Torso_Top_Left.stl" />
      </geometry>
    </collision>
    <inertial>
      <mass value="18.831528675460003" />
      <inertia ixx="0.5531359855664875" iyy="0.4439951879128532" izz="0.31759626621705994" ixy="-0.041468052340464905" ixz="0.049314153153277515" iyz="-0.00011456661259623901" />
      <origin xyz="0.105849249105629 -0.16298519527372674 0.0026080802670000723" rpy="1.5932781 0.98959443 -3.1036729" />
    </inertial>
  </link>
  <joint name="left shoulder pitch" type="revolute">
    <origin xyz="0.024425008982714366 -0.02995532458015677 0.00036285432413509086" rpy="-1.570796247544539 -0.6283185697272987 -1.7009570996876473" />
    <parent link="Torso_Top_Left" />
    <child link="RS_04_Rotor" />
    <limit effort="120" velocity="40" lower="2.04" upper="3.06" />
    <axis xyz="0 0 1" />
  </joint>
  <link name="RS_04_Rotor">
    <visual>
      <origin xyz="0 0 0" rpy="0 0 0" />
      <geometry>
        <mesh filename="meshes/RS_04_Rotor.stl" />
      </geometry>
      <material name="RS_04_Rotor_material">
        <color rgba="0.91764706 0.91764706 0.91764706 1" />
      </material>
    </visual>
    <collision>
      <origin xyz="0 0 0" rpy="0 0 0" />
      <geometry>
        <mesh filename="meshes/RS_04_Rotor.stl" />
      </geometry>
    </collision>
    <inertial>
      <mass value="1.50594063" />
      <inertia ixx="0.004986491196306936" iyy="0.005472315823548255" izz="0.003493349723498863" ixy="5.939540660920061e-05" ixz="-0.0008203955067710282" iyz="1.644680152730951e-05" />
      <origin xyz="0.0007793951031627056 0.00042201137524714425 -0.1267863528255389" rpy="0 1.5707963 0" />
    </inertial>
  </link>
  <joint name="right shoulder pitch" type="revolute">
    <origin xyz="0.1909522526089682 -0.02995532590025842 0.0002628555146248879" rpy="1.5707963075247102 0.6283185801607192 -1.4406356454008646" />
    <parent link="Torso_Top_Left" />
    <child link="RS_04_Rotor_2" />
    <limit effort="120" velocity="40" lower="2.619" upper="3.621" />
    <axis xyz="0 0 1" />
  </joint>
  <link name="RS_04_Rotor_2">
    <visual>
      <origin xyz="0 0 0" rpy="0 0 0" />
      <geometry>
        <mesh filename="meshes/RS_04_Rotor_2.stl" />
      </geometry>
      <material name="RS_04_Rotor_material_2">
        <color rgba="0.91764706 0.91764706 0.91764706 1" />
      </material>
    </visual>
    <collision>
      <origin xyz="0 0 0" rpy="0 0 0" />
      <geometry>
        <mesh filename="meshes/RS_04_Rotor_2.stl" />
      </geometry>
    </collision>
    <inertial>
      <mass value="1.5121783391049999" />
      <inertia ixx="0.004435397249314546" iyy="0.0052944306611141505" izz="0.004264987416273816" ixy="-0.0002598003293173021" ixz="3.922750168176236e-05" iyz="0.0004950990166335596" />
      <origin xyz="0.0004190771462494662 0.0005781370415853787 -0.12696878347273474" rpy="0 1.5707963 0" />
    </inertial>
  </link>
  <joint name="left hip pitch" type="revolute">
    <origin xyz="0.0836886262786379 -0.402760421846233 0.0003628562177818359" rpy="-2.679489613521826e-08 1.570796288901191 0.0" />
    <parent link="Torso_Top_Left" />
    <child link="RS_04_Rotor_3" />
    <limit effort="120" velocity="40" lower="-1.64" upper="1.64" />
    <axis xyz="0 0 1" />
  </joint>
  <link name="RS_04_Rotor_3">
    <visual>
      <origin xyz="0 0 0" rpy="0 0 0" />
      <geometry>
        <mesh filename="meshes/RS_04_Rotor_3.stl" />
      </geometry>
      <material name="RS_04_Rotor_material_3">
        <color rgba="0.91764706 0.91764706 0.91764706 1" />
      </material>
    </visual>
    <collision>
      <origin xyz="0 0 0" rpy="0 0 0" />
      <geometry>
        <mesh filename="meshes/RS_04_Rotor_3.stl" />
      </geometry>
    </collision>
    <inertial>
      <mass value="2.3975740853299996" />
      <inertia ixx="0.005405966400299497" iyy="0.007815028886180209" izz="0.008565367780360458" ixy="-1.2649152216850614e-05" ixz="4.229802716335362e-05" iyz="-5.08949648186298e-05" />
      <origin xyz="-0.006979133877391645 0.0003972662442528663 -0.11747947360060454" rpy="0 1.5707963 0" />
    </inertial>
  </link>
  <joint name="right hip pitch" type="revolute">
    <origin xyz="0.1316886278749738 -0.40276042146787466 0.00036286062283471393" rpy="-3.1415926267948957 1.5707962725326015 0.0" />
    <parent link="Torso_Top_Left" />
    <child link="RS_04_Rotor_4" />
    <limit effort="120" velocity="40" lower="0.05" upper="4.05" />
    <axis xyz="0 0 1" />
  </joint>
  <link name="RS_04_Rotor_4">
    <visual>
      <origin xyz="0 0 0" rpy="0 0 0" />
      <geometry>
        <mesh filename="meshes/RS_04_Rotor_4.stl" />
      </geometry>
      <material name="RS_04_Rotor_material_4">
        <color rgba="0.91764706 0.91764706 0.91764706 1" />
      </material>
    </visual>
    <collision>
      <origin xyz="0 0 0" rpy="0 0 0" />
      <geometry>
        <mesh filename="meshes/RS_04_Rotor_4.stl" />
      </geometry>
    </collision>
    <inertial>
      <mass value="2.397601849405" />
      <inertia ixx="0.009967743524184575" iyy="0.00781535841133868" izz="0.004004707270692186" ixy="3.190661100401802e-05" ixz="-0.0006243258291804489" iyz="-2.7585771692825293e-05" />
      <origin xyz="0.0069803814969581065 0.0002546901943471837 -0.1174844553161539" rpy="0 1.5707963 0" />
    </inertial>
  </link>
  <joint name="left shoulder yaw" type="revolute">
    <origin xyz="-0.012499999999999963 1.0450009692554367e-09 -0.17149999928993528" rpy="-7.179586503772435e-09 -1.5707963000000003 0.0" />
    <parent link="RS_04_Rotor" />
    <child link="RS_01_Rotor" />
    <limit effort="17" velocity="40" lower="-1" upper="2" />
    <axis xyz="0 0 1" />
  </joint>
  <link name="RS_01_Rotor">
    <visual>
      <origin xyz="0 0 0" rpy="0 0 0" />
      <geometry>
        <mesh filename="meshes/RS_01_Rotor.stl" />
      </geometry>
      <material name="RS_01_Rotor_material">
        <color rgba="0.64705882 0.64705882 0.64705882 1" />
      </material>
    </visual>
    <collision>
      <origin xyz="0 0 0" rpy="0 0 0" />
      <geometry>
        <mesh filename="meshes/RS_01_Rotor.stl" />
      </geometry>
    </collision>
    <inertial>
      <mass value="0.89890256" />
      <inertia ixx="0.0016843391207717348" iyy="0.0016541654829603859" izz="0.001883788000919158" ixy="0.0001031247300731018" ixz="-0.00010108056979707998" iyz="0.0006450905317577773" />
      <origin xyz="-0.07034193689931978 4.591606819003598e-05 -0.013254389923241721" rpy="3.1415927 0.76689767 -1.5707963" />
    </inertial>
  </link>
  <joint name="right shoulder yaw" type="revolute">
    <origin xyz="-3.7296467303438163e-10 -0.012700001588824082 -0.17150000072416888" rpy="1.570796373205103 1.570796288901191 0.0" />
    <parent link="RS_04_Rotor_2" />
    <child link="RS_01_Rotor_2" />
    <limit effort="17" velocity="40" lower="-1.481" upper="1" />
    <axis xyz="0 0 1" />
  </joint>
  <link name="RS_01_Rotor_2">
    <visual>
      <origin xyz="0 0 0" rpy="0 0 0" />
      <geometry>
        <mesh filename="meshes/RS_01_Rotor_2.stl" />
      </geometry>
      <material name="RS_01_Rotor_material_2">
        <color rgba="0.64705882 0.64705882 0.64705882 1" />
      </material>
    </visual>
    <collision>
      <origin xyz="0 0 0" rpy="0 0 0" />
      <geometry>
        <mesh filename="meshes/RS_01_Rotor_2.stl" />
      </geometry>
    </collision>
    <inertial>
      <mass value="0.9043950874749999" />
      <inertia ixx="0.0018764575785208126" iyy="0.0018629168293743954" izz="0.0015687659977742649" ixy="0.00011566896794102142" ixz="5.0842854185723597e-05" iyz="0.0002199207218625621" />
      <origin xyz="4.7452772316321314e-05 -0.07000681946157908 -0.01294571883652826" rpy="3.1415927 0.76689767 -1.5707963" />
    </inertial>
  </link>
  <joint name="left hip yaw" type="revolute">
    <origin xyz="-0.018700002008366415 2.1435917263446046e-11 -0.1320000000214359" rpy="2.679489619440787e-08 -1.5707962889011904 0.0" />
    <parent link="RS_04_Rotor_3" />
    <child link="RS_04_Rotor_5" />
    <limit effort="120" velocity="40" lower="2.64" upper="5.64" />
    <axis xyz="0 0 1" />
  </joint>
  <link name="RS_04_Rotor_5">
    <visual>
      <origin xyz="0 0 0" rpy="0 0 0" />
      <geometry>
        <mesh filename="meshes/RS_04_Rotor_5.stl" />
      </geometry>
      <material name="RS_04_Rotor_material_5">
        <color rgba="0.91764706 0.91764706 0.91764706 1" />
      </material>
    </visual>
    <collision>
      <origin xyz="0 0 0" rpy="0 0 0" />
      <geometry>
        <mesh filename="meshes/RS_04_Rotor_5.stl" />
      </geometry>
    </collision>
    <inertial>
      <mass value="1.464869118248" />
      <inertia ixx="0.004340584899402537" iyy="0.00512783433374757" izz="0.007097767164976971" ixy="-8.529722670586798e-05" ixz="-4.921746798563025e-06" iyz="0.0007428469682354404" />
      <origin xyz="0.06425397218850032 -0.0010807911547978328 -0.020888180298016264" rpy="0 1.5707963 0" />
    </inertial>
  </link>
  <joint name="left shoulder roll" type="revolute">
    <origin xyz="-0.07349999999999998 2.6794896579307448e-09 -0.012500000710064756" rpy="-3.1415926071795863 -1.5707963 0.0" />
    <parent link="RS_01_Rotor" />
    <child link="RS_01_Rotor_3" />
    <limit effort="17" velocity="40" lower="2.63" upper="3.64" />
    <axis xyz="0 0 1" />
  </joint>
  <link name="RS_01_Rotor_3">
    <visual>
      <origin xyz="0 0 0" rpy="0 0 0" />
      <geometry>
        <mesh filename="meshes/RS_01_Rotor_3.stl" />
      </geometry>
      <material name="RS_01_Rotor_material_3">
        <color rgba="0.64705882 0.64705882 0.64705882 1" />
      </material>
    </visual>
    <collision>
      <origin xyz="0 0 0" rpy="0 0 0" />
      <geometry>
        <mesh filename="meshes/RS_01_Rotor_3.stl" />
      </geometry>
    </collision>
    <inertial>
      <mass value="1.3844387" />
      <inertia ixx="0.0038801067322725546" iyy="0.003481074954786383" izz="0.0029190675018406064" ixy="-5.753291809806889e-05" ixz="0.00010526140063985741" iyz="-0.0001914467068938706" />
      <origin xyz="0.00034021384304762874 -4.047108945930609e-05 -0.11499137401252028" rpy="3.1415927 0.76689767 -1.5707963" />
    </inertial>
  </link>
  <joint name="right hip yaw" type="revolute">
    <origin xyz="0.018700000589129673 -5.393609593673521e-09 -0.13200000042436344" rpy="-3.1415926339744837 -1.5707962935875666 0.0" />
    <parent link="RS_04_Rotor_4" />
    <child link="RS_04_Rotor_6" />
    <limit effort="120" velocity="40" lower="1.74" upper="4.74" />
    <axis xyz="0 0 1" />
  </joint>
  <link name="RS_04_Rotor_6">
    <visual>
      <origin xyz="0 0 0" rpy="0 0 0" />
      <geometry>
        <mesh filename="meshes/RS_04_Rotor_6.stl" />
      </geometry>
      <material name="RS_04_Rotor_material_6">
        <color rgba="0.91764706 0.91764706 0.91764706 1" />
      </material>
    </visual>
    <collision>
      <origin xyz="0 0 0" rpy="0 0 0" />
      <geometry>
        <mesh filename="meshes/RS_04_Rotor_6.stl" />
      </geometry>
    </collision>
    <inertial>
      <mass value="1.464866268248" />
      <inertia ixx="0.0051355337053110486" iyy="0.004332547551451396" izz="0.007097779352708712" ixy="-7.779696443611667e-05" ixz="0.0007438101380820616" iyz="4.438823299069685e-05" />
      <origin xyz="0.0011672744170810614 -0.06425381141794081 -0.020872515197666277" rpy="0 1.5707963 0" />
    </inertial>
  </link>
  <joint name="right shoulder roll" type="revolute">
    <origin xyz="3.5226699869606026e-07 -0.0736999974843999 -0.012500050861371164" rpy="-1.5707962803846895 1.5707962488400797 0.0" />
    <parent link="RS_01_Rotor_2" />
    <child link="RS_01_Rotor_4" />
    <limit effort="17" velocity="40" lower="-1.881" upper="-1.479" />
    <axis xyz="0 0 1" />
  </joint>
  <link name="RS_01_Rotor_4">
    <visual>
      <origin xyz="0 0 0" rpy="0 0 0" />
      <geometry>
        <mesh filename="meshes/RS_01_Rotor_4.stl" />
      </geometry>
      <material name="RS_01_Rotor_material_4">
        <color rgba="0.64705882 0.64705882 0.64705882 1" />
      </material>
    </visual>
    <collision>
      <origin xyz="0 0 0" rpy="0 0 0" />
      <geometry>
        <mesh filename="meshes/RS_01_Rotor_4.stl" />
      </geometry>
    </collision>
    <inertial>
      <mass value="1.3908071250299998" />
      <inertia ixx="0.0024605763939116337" iyy="0.0037909810510146536" izz="0.0040621750588155535" ixy="-0.00021239674122343965" ixz="0.0001600917335983456" iyz="0.00015105827947657594" />
      <origin xyz="0.0003398853031190067 0.00025115408369129707 -0.11515261387824338" rpy="3.1415927 0.76689767 -1.5707963" />
    </inertial>
  </link>
  <joint name="left hip roll" type="revolute">
    <origin xyz="0.11430000143082522 -3.193900383752224e-09 -0.020000000238371677" rpy="-3.1415925071795865 1.5707963000000005 0.0" />
    <parent link="RS_04_Rotor_5" />
    <child link="RS_01_Rotor_5" />
    <limit effort="17" velocity="40" lower="-4.0" upper="1.0" />
    <axis xyz="0 0 1" />
  </joint>
  <link name="RS_01_Rotor_5">
    <visual>
      <origin xyz="0 0 0" rpy="0 0 0" />
      <geometry>
        <mesh filename="meshes/RS_01_Rotor_5.stl" />
      </geometry>
      <material name="RS_01_Rotor_material_5">
        <color rgba="0.64705882 0.64705882 0.64705882 1" />
      </material>
    </visual>
    <collision>
      <origin xyz="0 0 0" rpy="0 0 0" />
      <geometry>
        <mesh filename="meshes/RS_01_Rotor_5.stl" />
      </geometry>
    </collision>
    <inertial>
      <mass value="2.09780425533" />
      <inertia ixx="0.00572928787275102" iyy="0.004754016123744843" izz="0.005018487746359435" ixy="0.0004511000970734457" ixz="-1.7449946395238788e-06" iyz="0.0011581376815751666" />
      <origin xyz="0.010293093882242598 0.0036524322721237868 -0.10454561959862488" rpy="3.1415927 0.76689767 -1.5707963" />
    </inertial>
  </link>
  <joint name="left elbow pitch" type="revolute">
    <origin xyz="-8.949342570618857e-10 -0.012500000000000008 -0.15050000000000002" rpy="1.5707963928204127 1.5707963000000005 0.0" />
    <parent link="RS_01_Rotor_3" />
    <child link="RS_01_Rotor_6" />
    <limit effort="17" velocity="40" lower="-2.06" upper="-1.08" />
    <axis xyz="0 0 1" />
  </joint>
  <link name="RS_01_Rotor_6">
    <visual>
      <origin xyz="0 0 0" rpy="0 0 0" />
      <geometry>
        <mesh filename="meshes/RS_01_Rotor_6.stl" />
      </geometry>
      <material name="RS_01_Rotor_material_6">
        <color rgba="0.64705882 0.64705882 0.64705882 1" />
      </material>
    </visual>
    <collision>
      <origin xyz="0 0 0" rpy="0 0 0" />
      <geometry>
        <mesh filename="meshes/RS_01_Rotor_6.stl" />
      </geometry>
    </collision>
    <inertial>
      <mass value="0.89890256" />
      <inertia ixx="0.002258808290079867" iyy="0.0013472741712001737" izz="0.001617613442738517" ixy="-4.560124181390866e-05" ixz="-1.743593474948533e-05" iyz="8.644725952417546e-05" />
      <origin xyz="4.5811521886467546e-05 0.0703363884063435 -0.013254389743898438" rpy="3.1415927 0.76689767 -1.5707963" />
    </inertial>
  </link>
  <joint name="right hip roll" type="revolute">
    <origin xyz="0.00036835123268656907 -0.11429999986219413 -0.019935050164893164" rpy="-1.5707962535897932 -1.5707962535897941 0.0" />
    <parent link="RS_04_Rotor_6" />
    <child link="RS_01_Rotor_7" />
    <limit effort="17" velocity="40" lower="2.25" upper="4.49" />
    <axis xyz="0 0 1" />
  </joint>
  <link name="RS_01_Rotor_7">
    <visual>
      <origin xyz="0 0 0" rpy="0 0 0" />
      <geometry>
        <mesh filename="meshes/RS_01_Rotor_7.stl" />
      </geometry>
      <material name="RS_01_Rotor_material_7">
        <color rgba="0.64705882 0.64705882 0.64705882 1" />
      </material>
    </visual>
    <collision>
      <origin xyz="0 0 0" rpy="0 0 0" />
      <geometry>
        <mesh filename="meshes/RS_01_Rotor_7.stl" />
      </geometry>
    </collision>
    <inertial>
      <mass value="2.097754839405" />
      <inertia ixx="0.004825310410663815" iyy="0.0063944305813692336" izz="0.004281759739662401" ixy="0.0006020381314769578" ixz="-0.0005635017094712674" iyz="4.145287171967299e-06" />
      <origin xyz="0.003651253677969219 0.010292845891687726 -0.10454532276782534" rpy="3.1415927 0.76689767 -1.5707963" />
    </inertial>
  </link>
  <joint name="right elbow pitch" type="revolute">
    <origin xyz="-8.893203283164008e-10 0.012699999522538107 -0.1504999997314119" rpy="-1.5707962803846904 -1.57079628890119 0.0" />
    <parent link="RS_01_Rotor_4" />
    <child link="RS_01_Rotor_8" />
    <limit effort="17" velocity="40" lower="-3.819" upper="3.821" />
    <axis xyz="0 0 1" />
  </joint>
  <link name="RS_01_Rotor_8">
    <visual>
      <origin xyz="0 0 0" rpy="0 0 0" />
      <geometry>
        <mesh filename="meshes/RS_01_Rotor_8.stl" />
      </geometry>
      <material name="RS_01_Rotor_material_8">
        <color rgba="0.64705882 0.64705882 0.64705882 1" />
      </material>
    </visual>
    <collision>
      <origin xyz="0 0 0" rpy="0 0 0" />
      <geometry>
        <mesh filename="meshes/RS_01_Rotor_8.stl" />
      </geometry>
    </collision>
    <inertial>
      <mass value="0.9043038556249999" />
      <inertia ixx="0.0019258881399727868" iyy="0.0019047544351297292" izz="0.0014915483990721426" ixy="-2.7716527667346985e-05" ixz="5.198563176091067e-05" iyz="6.748709305008896e-05" />
      <origin xyz="4.379038547428254e-05 -0.07031155327557514 -0.012946377213447343" rpy="3.1415927 0.76689767 -1.5707963" />
    </inertial>
  </link>
  <joint name="left hand roll" type="revolute">
    <origin xyz="7.100647534674653e-10 0.07350000000000001 -0.012500000000000018" rpy="1.5707963999999996 -1.5707963 0.0" />
    <parent link="RS_01_Rotor_6" />
    <child link="RS_01_Rotor_9" />
    <limit effort="17" velocity="40" lower="-2.06" upper="-1.08" />
    <axis xyz="0 0 1" />
  </joint>
  <link name="RS_01_Rotor_9">
    <visual>
      <origin xyz="0 0 0" rpy="0 0 0" />
      <geometry>
        <mesh filename="meshes/RS_01_Rotor_9.stl" />
      </geometry>
      <material name="RS_01_Rotor_material_9">
        <color rgba="0.64705882 0.64705882 0.64705882 1" />
      </material>
    </visual>
    <collision>
      <origin xyz="0 0 0" rpy="0 0 0" />
      <geometry>
        <mesh filename="meshes/RS_01_Rotor_9.stl" />
      </geometry>
    </collision>
    <inertial>
      <mass value="0.71649812" />
      <inertia ixx="0.0007975220243512549" iyy="0.0014480975988133216" izz="0.0013403757516699706" ixy="-4.7590220855654515e-05" ixz="7.799465338013546e-05" iyz="0.00011874555103715594" />
      <origin xyz="-0.007563155163045606 -0.004164177568605618 -0.1022198837640559" rpy="3.1415927 0.76689767 -1.5707963" />
    </inertial>
  </link>
  <joint name="left knee pitch" type="revolute">
    <origin xyz="0.018700001420129515 2.1435901664812462e-11 -0.12050000002143592" rpy="1.5707963928204132 2.220446049250313e-16 1.5707963000000005" />
    <parent link="RS_01_Rotor_5" />
    <child link="RS_04_Rotor_7" />
    <limit effort="120" velocity="40" lower="-2.5" upper="0.5" />
    <axis xyz="0 0 1" />
  </joint>
  <link name="RS_04_Rotor_7">
    <visual>
      <origin xyz="0 0 0" rpy="0 0 0" />
      <geometry>
        <mesh filename="meshes/RS_04_Rotor_7.stl" />
      </geometry>
      <material name="RS_04_Rotor_material_7">
        <color rgba="0.91764706 0.91764706 0.91764706 1" />
      </material>
    </visual>
    <collision>
      <origin xyz="0 0 0" rpy="0 0 0" />
      <geometry>
        <mesh filename="meshes/RS_04_Rotor_7.stl" />
      </geometry>
    </collision>
    <inertial>
      <mass value="1.3548411100000002" />
      <inertia ixx="0.005578348852259086" iyy="0.003969458823128128" izz="0.007808074998011351" ixy="-0.00022979683258007074" ixz="0.0002835413966149501" iyz="-3.0448980796311694e-05" />
      <origin xyz="0.024074149859733777 -0.05798722812175579 -0.004855200857848546" rpy="0 1.5707963 0" />
    </inertial>
  </link>
  <joint name="right knee pitch" type="revolute">
    <origin xyz="-5.225005081377354e-10 0.018699998579870557 -0.12050000248117687" rpy="1.5707963 -4.641020634466031e-08 -3.141592653589792" />
    <parent link="RS_01_Rotor_7" />
    <child link="RS_04_Rotor_8" />
    <limit effort="120" velocity="40" lower="-0.5" upper="2.5" />
    <axis xyz="0 0 1" />
  </joint>
  <link name="RS_04_Rotor_8">
    <visual>
      <origin xyz="0 0 0" rpy="0 0 0" />
      <geometry>
        <mesh filename="meshes/RS_04_Rotor_8.stl" />
      </geometry>
      <material name="RS_04_Rotor_material_8">
        <color rgba="0.91764706 0.91764706 0.91764706 1" />
      </material>
    </visual>
    <collision>
      <origin xyz="0 0 0" rpy="0 0 0" />
      <geometry>
        <mesh filename="meshes/RS_04_Rotor_8.stl" />
      </geometry>
    </collision>
    <inertial>
      <mass value="1.35483828" />
      <inertia ixx="0.005577298765218677" iyy="0.003969488582128794" izz="0.007807059307660414" ixy="0.00045577114225811853" ixz="-0.0002891275044363122" iyz="2.904567597801843e-05" />
      <origin xyz="-0.024070518426869206 -0.057983520675797554 -0.004854984133664851" rpy="0 1.5707963 0" />
    </inertial>
  </link>
  <joint name="right hand roll" type="revolute">
    <origin xyz="3.529497187571007e-08 -0.07449999902199926 -0.012501018201999262" rpy="-1.5707963071795865 1.5707963 0.0" />
    <parent link="RS_01_Rotor_8" />
    <child link="RS_01_Rotor_10" />
    <limit effort="17" velocity="40" lower="-0.501" upper="0.501" />
    <axis xyz="0 0 1" />
  </joint>
  <link name="RS_01_Rotor_10">
    <visual>
      <origin xyz="0 0 0" rpy="0 0 0" />
      <geometry>
        <mesh filename="meshes/RS_01_Rotor_10.stl" />
      </geometry>
      <material name="RS_01_Rotor_material_10">
        <color rgba="0.64705882 0.64705882 0.64705882 1" />
      </material>
    </visual>
    <collision>
      <origin xyz="0 0 0" rpy="0 0 0" />
      <geometry>
        <mesh filename="meshes/RS_01_Rotor_10.stl" />
      </geometry>
    </collision>
    <inertial>
      <mass value="0.71650123" />
      <inertia ixx="0.0007975824792275976" iyy="0.0014548358037070747" izz="0.0013337706004214781" ixy="9.800567419865285e-05" ixz="-9.856676542566098e-05" iyz="0.00011969710863173036" />
      <origin xyz="0.007556054221390037 -0.004164174654912105 -0.10222028132975519" rpy="3.1415927 0.76689767 -1.5707963" />
    </inertial>
  </link>
  <joint name="left hand gripper" type="revolute">
    <origin xyz="-0.019107094000452466 -1.6885888027392335e-05 -0.09775000004019237" rpy="-1.5707963 0.0 1.5707963" />
    <parent link="RS_01_Rotor_9" />
    <child link="RS_01_Rotor_11" />
    <limit effort="17" velocity="40" lower="-0.5" upper="2.07" />
    <axis xyz="0 0 1" />
  </joint>
  <link name="RS_01_Rotor_11">
    <visual>
      <origin xyz="0 0 0" rpy="0 0 0" />
      <geometry>
        <mesh filename="meshes/RS_01_Rotor_11.stl" />
      </geometry>
      <material name="RS_01_Rotor_material_11">
        <color rgba="0.64705882 0.64705882 0.64705882 1" />
      </material>
    </visual>
    <collision>
      <origin xyz="0 0 0" rpy="0 0 0" />
      <geometry>
        <mesh filename="meshes/RS_01_Rotor_11.stl" />
      </geometry>
    </collision>
    <inertial>
      <mass value="0.29472087" />
      <inertia ixx="0.0005487838329605582" iyy="0.0001998018182382957" izz="0.0006024338080333796" ixy="-0.00012320773938756754" ixz="3.8246712966694546e-05" iyz="9.783039564203536e-05" />
      <origin xyz="0.011533255480913175 0.03127080257399953 -0.030670626758674924" rpy="3.1415927 0.76689767 -1.5707963" />
    </inertial>
  </link>
  <joint name="left ankle pitch" type="revolute">
    <origin xyz="0.0014746615 -0.18 0.0010000000000000009" rpy="0.0 0.0 1.5707963" />
    <parent link="RS_04_Rotor_7" />
    <child link="RS_01_Stator" />
    <limit effort="17" velocity="40" lower="0.9" upper="2.7" />
    <axis xyz="0 0 1" />
  </joint>
  <link name="RS_01_Stator">
    <visual>
      <origin xyz="0 0 0" rpy="0 0 0" />
      <geometry>
        <mesh filename="meshes/RS_01_Stator.stl" />
      </geometry>
      <material name="RS_01_Stator_material">
        <color rgba="0.61568627 0.81176471 0.92941176 1" />
      </material>
    </visual>
    <collision>
      <origin xyz="0 0 0" rpy="0 0 0" />
      <geometry>
        <mesh filename="meshes/RS_01_Stator.stl" />
      </geometry>
    </collision>
    <inertial>
      <mass value="1.338872074976" />
      <inertia ixx="0.0025939512432408755" iyy="0.003698412905634625" izz="0.0030517183583497567" ixy="-4.656819408930256e-05" ixz="0.00021444497581353487" iyz="1.0558320754498414e-05" />
      <origin xyz="-0.02553837576550215 0.017161713596197954 -0.002677054992928269" rpy="3.1413879 -1.5635875 -3.1354067" />
    </inertial>
  </link>
  <joint name="right ankle pitch" type="revolute">
    <origin xyz="-0.001474653146162871 -0.17999999865292787 0.0009999999999999731" rpy="9.282041313340983e-08 2.220446049250313e-16 -3.1415926071795863" />
    <parent link="RS_04_Rotor_8" />
    <child link="RS_01_Stator_2" />
    <limit effort="17" velocity="40" lower="-1.5" upper="0.7" />
    <axis xyz="0 0 1" />
  </joint>
  <link name="RS_01_Stator_2">
    <visual>
      <origin xyz="0 0 0" rpy="0 0 0" />
      <geometry>
        <mesh filename="meshes/RS_01_Stator_2.stl" />
      </geometry>
      <material name="RS_01_Stator_material_2">
        <color rgba="0.61568627 0.81176471 0.92941176 1" />
      </material>
    </visual>
    <collision>
      <origin xyz="0 0 0" rpy="0 0 0" />
      <geometry>
        <mesh filename="meshes/RS_01_Stator_2.stl" />
      </geometry>
    </collision>
    <inertial>
      <mass value="1.3388721249759998" />
      <inertia ixx="0.003322147622899236" iyy="0.0037239782209600772" izz="0.002304537208081858" ixy="-2.4139448579446697e-05" ixz="0.0002578360795077843" iyz="8.565778969006549e-05" />
      <origin xyz="0.025492396536919117 0.017432908893335455 -0.0026770535423528636" rpy="3.1413879 -1.5635875 -3.1354067" />
    </inertial>
  </link>
  <joint name="right hand gripper" type="revolute">
    <origin xyz="0.019107094000452466 -1.6885888027392335e-05 -0.09775000004019237" rpy="-1.5707963 0.0 -1.5707963" />
    <parent link="RS_01_Rotor_10" />
    <child link="RS_01_Rotor_12" />
    <limit effort="17" velocity="40" lower="-0.5" upper="2.07" />
    <axis xyz="0 0 1" />
  </joint>
  <link name="RS_01_Rotor_12">
    <visual>
      <origin xyz="0 0 0" rpy="0 0 0" />
      <geometry>
        <mesh filename="meshes/RS_01_Rotor_12.stl" />
      </geometry>
      <material name="RS_01_Rotor_material_12">
        <color rgba="0.64705882 0.64705882 0.64705882 1" />
      </material>
    </visual>
    <collision>
      <origin xyz="0 0 0" rpy="0 0 0" />
      <geometry>
        <mesh filename="meshes/RS_01_Rotor_12.stl" />
      </geometry>
    </collision>
    <inertial>
      <mass value="0.29471965" />
      <inertia ixx="0.000548420910562744" iyy="0.00019870251985419505" izz="0.0006036540856531655" ixy="0.00012334104468828848" ixz="-3.655326303439024e-05" iyz="9.558313982486888e-05" />
      <origin xyz="-0.01155046440325713 0.031270601437517365 -0.030670677078880805" rpy="3.1415927 0.76689767 -1.5707963" />
    </inertial>
  </link>
</robot>