<robot name="robot">
  <link name="base">
    <inertial>
      <origin rpy="0.0 0.0 0.0" xyz="0.0 0.0 0.0" />
      <mass value="0.001" />
      <inertia ixx="0.0001" ixy="0.0" ixz="0.0" iyy="0.0001" iyz="0.0" izz="0.0001" />
      </inertial>
    </link>
  <joint name="floating_base" type="fixed">
    <origin rpy="0 0 0" xyz="0 0 0.0" />
    <parent link="base" />
    <child link="trunk" />
    </joint>
  <link name="trunk">
    <inertial>
      <origin rpy="0.0 0.0 0.0" xyz="-0.00051930492 0.00030343937 0.21140495" />
      <mass value="13.05315" />
      <inertia ixx="0.56635021" ixy="-5.2717245e-05" ixz="-0.00020117771" iyy="0.462714" iyz="0.00062003391" izz="0.13193241" />
      </inertial>
    <visual>
      <origin rpy="0.0 0.0 0.0" xyz="0.0 0.0 0.0" />
      <geometry>
        <mesh filename="meshes/trunk.stl" scale="1e-3 1e-3 1e-3" />
        </geometry>
      </visual>
    <collision>
      <origin rpy="0.0 0.0 0.0" xyz="0.0 0.0 0.0" />
      <geometry>
        <mesh filename="meshes/trunk.stl" scale="1e-3 1e-3 1e-3" />
        </geometry>
      </collision>
    </link>
  <joint name="L_hip_y" type="revolute">
    <origin rpy="0 0 0" xyz="0 0.1577 0" />
    <parent link="trunk" />
    <child link="L_buttock" />
    <axis xyz="0.0 1.0 0" />
    <limit effort="120" lower="-3.14" upper="3.14" velocity="5" />
    <dynamics damping="0" friction="0" />
    </joint>
  <link name="L_buttock">
    <inertial>
      <origin rpy="0.0 0.0 0.0" xyz="0.0012918323 -0.0018432774 2.2794594e-05" />
      <mass value="1.2990888" />
      <inertia ixx="0.0020931102" ixy="-1.0314072e-05" ixz="5.1795876e-07" iyy="0.0013118768" iyz="-4.0767562e-07" izz="0.0015000916" />
      </inertial>
    <visual>
      <origin rpy="3.1415926 0 0" xyz="0 0 0" />
      <geometry>
        <mesh filename="meshes/buttock.stl" scale="1e-3 1e-3 1e-3" />
        </geometry>
      </visual>
    <collision>
      <origin rpy="3.1415926 0 0" xyz="0 0 0" />
      <geometry>
        <mesh filename="meshes/buttock.stl" scale="1e-3 1e-3 1e-3" />
        </geometry>
      </collision>
    </link>
  <joint name="L_hip_x" type="revolute">
    <origin rpy="0.0 0.0 0.0" xyz="0 0 0" />
    <parent link="L_buttock" />
    <child link="L_leg" />
    <axis xyz="1.0 0.0 0.0" />
    <limit effort="60" lower="-0.523" upper="2.093" velocity="5" />
    <dynamics damping="0" friction="0" />
    </joint>
  <link name="L_leg">
    <inertial>
      <origin rpy="0.0 0.0 0.0" xyz="0.00070860204 -2.2435483e-05 -0.11035196" />
      <mass value="1.3398346" />
      <inertia ixx="0.00350784" ixy="3.4919088e-07" ixz="-0.00015597216" iyy="0.0037534076" iyz="-7.0069817e-08" izz="0.0018582238" />
      </inertial>
    <visual>
      <geometry>
        <mesh filename="meshes/leg.stl" scale="1e-3 1e-3 1e-3" />
        </geometry>
      </visual>
    <collision>
      <origin rpy="0 0 0" xyz="0 0 0" />
      <geometry>
        <mesh filename="meshes/leg.stl" scale="1e-3 1e-3 1e-3" />
        </geometry>
      </collision>
    </link>
  <joint name="L_hip_z" type="revolute">
    <origin rpy="0.0 0 0.0" xyz="0 0 0" />
    <parent link="L_leg" />
    <child link="L_thigh" />
    <axis xyz="0.0 0.0 1.0" />
    <limit effort="60" lower="-3.14" upper="3.14" velocity="5" />
    <dynamics damping="0" friction="0" />
    </joint>
  <link name="L_thigh">
    <inertial>
      <origin rpy="0.0 0.0 0.0" xyz="-0.00040735676 0.0013053813 -0.29165284" />
      <mass value="1.9399504" />
      <inertia ixx="0.0044937128" ixy="2.1462344e-05" ixz="1.0739651e-05" iyy="0.0060757923" iyz="-2.6643735e-05" izz="0.0029354143" />
      </inertial>
    <visual>
      <geometry>
        <mesh filename="meshes/mthigh.stl" scale="1e-3 1e-3 1e-3" />
        </geometry>
      </visual>
    <collision>
      <origin rpy="0 0 0" xyz="0 0 0" />
      <geometry>
        <mesh filename="meshes/mthigh.stl" scale="1e-3 1e-3 1e-3" />
        </geometry>
      </collision>
    </link>
  <joint name="L_knee" type="revolute">
    <origin rpy="0.0 0.0 0.0" xyz="0 0 -0.3" />
    <parent link="L_thigh" />
    <child link="L_calf" />
    <axis xyz="0.0 1.0 0.0" />
    <limit effort="120" lower="-1.919" upper="1.919" velocity="5" />
    <dynamics damping="0" friction="0" />
    </joint>
  <link name="L_calf">
    <inertial>
      <origin rpy="0.0 0.0 0.0" xyz="-0.0019535236 -0.0043433803 -0.13404794" />
      <mass value="1.544772" />
      <inertia ixx="0.0097259036" ixy="-4.7543777e-05" ixz="-0.00019535575" iyy="0.0098345988" iyz="-0.00037837351" izz="0.0014598955" />
      </inertial>
    <visual>
      <geometry>
        <mesh filename="meshes/mcalf.stl" scale="1e-3 1e-3 1e-3" />
        </geometry>
      </visual>
    <collision>
      <origin rpy="0 0 0" xyz="0 0 0" />
      <geometry>
        <mesh filename="meshes/mcalf.stl" scale="1e-3 1e-3 1e-3" />
        </geometry>
      </collision>
    </link>
  <joint name="L_ankle_y" type="revolute">
    <origin rpy="0.0 0.0 0.0" xyz="0 0 -0.3" />
    <parent link="L_calf" />
    <child link="L_foot" />
    <axis xyz="0.0 1.0 0.0" />
    <limit effort="17" lower="-0.698" upper="0.698" velocity="5" />
    <dynamics damping="0" friction="0" />
    </joint>
  <link name="L_foot">
    <inertial>
      <origin rpy="0.0 0.0 0.0" xyz="0.023366504 0.014827011 -0.016531354" />
      <mass value="0.54237266" />
      <inertia ixx="0.00025746264" ixy="-3.4761901e-05" ixz="3.5533704e-05" iyy="0.0019652138" iyz="3.5259776e-06" izz="0.0021498817" />
      </inertial>
    <visual>
      <geometry>
        <mesh filename="meshes/mfoot.stl" scale="1e-3 1e-3 1e-3" />
        </geometry>
      </visual>
    <collision>
      <origin rpy="0.0 0.0 0.0" xyz="30e-3 -11e-3 -20e-3" />
      <geometry>
        <box size="220e-3 80e-3 15e-3" />
        </geometry>
      </collision>
    </link>
  <joint name="R_hip_y" type="revolute">
    <origin rpy="0 0 0" xyz="0 -0.1577 0" />
    <parent link="trunk" />
    <child link="R_buttock" />
    <axis xyz="0.0 1.0 0" />
    <limit effort="120" lower="-3.14" upper="3.14" velocity="5" />
    <dynamics damping="0" friction="0" />
    </joint>
  <link name="R_buttock">
    <inertial>
      <origin rpy="0.0 0.0 0.0" xyz="0.0012918323 0.0018432774 2.2794594e-05" />
      <mass value="1.2990888" />
      <inertia ixx="0.0020931102" ixy="1.0314072e-05" ixz="5.1795876e-07" iyy="0.0013118768" iyz="4.0767562e-07" izz="0.0015000916" />
      </inertial>
    <visual>
      <origin rpy="0 0 0" xyz="0 0 0" />
      <geometry>
        <mesh filename="meshes/buttock.stl" scale="1e-3 1e-3 1e-3" />
        </geometry>
      </visual>
    <collision>
      <origin rpy="0 0 0" xyz="0 0 0" />
      <geometry>
        <mesh filename="meshes/buttock.stl" scale="1e-3 1e-3 1e-3" />
        </geometry>
      </collision>
    </link>
  <joint name="R_hip_x" type="revolute">
    <origin rpy="0.0 0.0 0.0" xyz="0 0 0" />
    <parent link="R_buttock" />
    <child link="R_leg" />
    <axis xyz="1.0 0.0 0.0" />
    <limit effort="60" lower="-2.093" upper="0.523" velocity="5" />
    <dynamics damping="0" friction="0" />
    </joint>
  <link name="R_leg">
    <inertial>
      <origin rpy="0.0 0.0 0.0" xyz="0.00070860204 2.2435483e-05 -0.11035196" />
      <mass value="1.3398346" />
      <inertia ixx="0.00350784" ixy="-3.4919088e-07" ixz="-0.00015597216" iyy="0.0037534076" iyz="7.0069817e-08" izz="0.0018582238" />
      </inertial>
    <visual>
      <geometry>
        <mesh filename="meshes/leg.stl" scale="1e-3 1e-3 1e-3" />
        </geometry>
      </visual>
    <collision>
      <origin rpy="0 0 0" xyz="0 0 0" />
      <geometry>
        <mesh filename="meshes/leg.stl" scale="1e-3 1e-3 1e-3" />
        </geometry>
      </collision>
    </link>
  <joint name="R_hip_z" type="revolute">
    <origin rpy="0.0 0 0.0" xyz="0 0 0" />
    <parent link="R_leg" />
    <child link="R_thigh" />
    <axis xyz="0.0 0.0 1.0" />
    <limit effort="60" lower="-3.14" upper="3.14" velocity="5" />
    <dynamics damping="0" friction="0" />
    </joint>
  <link name="R_thigh">
    <inertial>
      <origin rpy="0.0 0.0 0.0" xyz="-0.00040735676 -0.0013053813 -0.29165284" />
      <mass value="1.9399504" />
      <inertia ixx="0.0044937128" ixy="-2.1462344e-05" ixz="1.0739651e-05" iyy="0.0060757923" iyz="2.6643735e-05" izz="0.0029354143" />
      </inertial>
    <visual>
      <geometry>
        <mesh filename="meshes/thigh.stl" scale="1e-3 1e-3 1e-3" />
        </geometry>
      </visual>
    <collision>
      <origin rpy="0 0 0" xyz="0 0 0" />
      <geometry>
        <mesh filename="meshes/thigh.stl" scale="1e-3 1e-3 1e-3" />
        </geometry>
      </collision>
    </link>
  <joint name="R_knee" type="revolute">
    <origin rpy="0.0 0.0 0.0" xyz="0 0 -0.3" />
    <parent link="R_thigh" />
    <child link="R_calf" />
    <axis xyz="0.0 1.0 0.0" />
    <limit effort="120" lower="-1.919" upper="1.919" velocity="5" />
    <dynamics damping="0" friction="0" />
    </joint>
  <link name="R_calf">
    <inertial>
      <origin rpy="0.0 0.0 0.0" xyz="-0.0019535236 0.0043433803 -0.13404794" />
      <mass value="1.544772" />
      <inertia ixx="0.0097259036" ixy="4.7543777e-05" ixz="-0.00019535575" iyy="0.0098345988" iyz="0.00037837351" izz="0.0014598955" />
      </inertial>
    <visual>
      <geometry>
        <mesh filename="meshes/calf.stl" scale="1e-3 1e-3 1e-3" />
        </geometry>
      </visual>
    <collision>
      <origin rpy="0 0 0" xyz="0 0 0" />
      <geometry>
        <mesh filename="meshes/calf.stl" scale="1e-3 1e-3 1e-3" />
        </geometry>
      </collision>
    </link>
  <joint name="R_ankle_y" type="revolute">
    <origin rpy="0.0 0.0 0.0" xyz="0 0 -0.3" />
    <parent link="R_calf" />
    <child link="R_foot" />
    <axis xyz="0.0 1.0 0.0" />
    <limit effort="17" lower="-0.698" upper="0.698" velocity="5" />
    <dynamics damping="0" friction="0" />
    </joint>
  <link name="R_foot">
    <inertial>
      <origin rpy="0.0 0.0 0.0" xyz="0.023366504 0.014827011 -0.016531354" />
      <mass value="0.54237266" />
      <inertia ixx="0.00025746264" ixy="-3.4761901e-05" ixz="3.5533704e-05" iyy="0.0019652138" iyz="3.5259776e-06" izz="0.0021498817" />
      </inertial>
    <visual>
      <geometry>
        <mesh filename="meshes/foot.stl" scale="1e-3 1e-3 1e-3" />
        </geometry>
      </visual>
    <collision>
      <origin rpy="0.0 0.0 0.0" xyz="30e-3 11e-3 -20e-3" />
      <geometry>
        <box size="220e-3 80e-3 15e-3" />
        </geometry>
      </collision>
    </link>
  <joint name="L_shoulder_y" type="fixed">
    <origin rpy="0 0 0" xyz="0 0.255 0.45" />
    <parent link="trunk" />
    <child link="L_clav" />
    <axis xyz="0.0 1.0 0.0" />
    <limit effort="60" lower="-3.1416" upper="3.1416" velocity="0" />
    <dynamics damping="0" friction="0" />
    </joint>
  <link name="L_clav">
    <inertial>
      <origin rpy="0.0 0.0 0.0" xyz="0.0012122056 -0.0015095858 -9.3677479e-05" />
      <mass value="1.1246895" />
      <inertia ixx="0.0017070766" ixy="-2.3820729e-06" ixz="-6.7619904e-06" iyy="0.0010595629" iyz="-3.2352008e-07" izz="0.001122517" />
      </inertial>
    <visual>
      <origin rpy="-3.1415926 0 0" xyz="0 0 0" />
      <geometry>
        <mesh filename="meshes/clav.stl" scale="1e-3 1e-3 1e-3" />
        </geometry>
      </visual>
    <collision>
      <origin rpy="-3.1415926 0 0" xyz="0 0 0" />
      <geometry>
        <mesh filename="meshes/clav.stl" scale="1e-3 1e-3 1e-3" />
        </geometry>
      </collision>
    </link>
  <joint name="L_shoulder_x" type="fixed">
    <origin rpy="0.0 0.0 0.0" xyz="0 0 0" />
    <parent link="L_clav" />
    <child link="L_scapula" />
    <axis xyz="1.0 0.0 0.0" />
    <limit effort="60" lower="0" upper="3.1416" velocity="0" />
    <dynamics damping="0" friction="0" />
    </joint>
  <link name="L_scapula">
    <inertial>
      <origin rpy="0.0 0.0 0.0" xyz="0.0038106082 -0.0001642433 -0.095219061" />
      <mass value="0.65454544" />
      <inertia ixx="0.0011234347" ixy="-4.6391796e-06" ixz="-0.00021802428" iyy="0.0011878253" iyz="-1.8375484e-06" izz="0.00058824357" />
      </inertial>
    <visual>
      <geometry>
        <mesh filename="meshes/scap.stl" scale="1e-3 1e-3 1e-3" />
        </geometry>
      </visual>
    <collision>
      <geometry>
        <mesh filename="meshes/scap.stl" scale="1e-3 1e-3 1e-3" />
        </geometry>
      </collision>
    </link>
  <joint name="L_shoulder_z" type="fixed">
    <origin rpy="0.0 0.0 0.0" xyz="0 0 0" />
    <parent link="L_scapula" />
    <child link="L_uarm" />
    <axis xyz="0.0 0.0 1.0" />
    <limit effort="17" lower="-3.14" upper="3.14" velocity="0" />
    <dynamics damping="0" friction="0" />
    </joint>
  <link name="L_uarm">
    <inertial>
      <origin rpy="0.0 0.0 0.0" xyz="-0.0039088302 0.00017072539 -0.22223086" />
      <mass value="0.58244405" />
      <inertia ixx="0.00083861306" ixy="-9.1542325e-08" ixz="0" iyy="0.00067605212" iyz="-2.7860944e-06" izz="0.0003615168" />
      </inertial>
    <visual>
      <geometry>
        <mesh filename="meshes/uarm.stl" scale="1e-3 1e-3 1e-3" />
        </geometry>
      </visual>
    <collision>
      <geometry>
        <mesh filename="meshes/uarm.stl" scale="1e-3 1e-3 1e-3" />
        </geometry>
      </collision>
    </link>
  <joint name="L_elbow_x" type="fixed">
    <origin rpy="0.0 0.0 0.0" xyz="0 0 -0.23" />
    <parent link="L_uarm" />
    <child link="L_farm" />
    <axis xyz="1.0 0 0.0" />
    <limit effort="17" lower="-1.9199" upper="1.9199" velocity="0" />
    <dynamics damping="0" friction="0" />
    </joint>
  <link name="L_farm">
    <inertial>
      <origin rpy="0.0 0.0 0.0" xyz="-0.0024082691 0.00017091831 -0.14069589" />
      <mass value="0.66002606" />
      <inertia ixx="0.0016198862" ixy="3.700055e-06" ixz="0.00013980511" iyy="0.0016516658" iyz="2.349341e-06" izz="0.00054139396" />
      </inertial>
    <visual>
      <geometry>
        <mesh filename="meshes/farm.stl" scale="1e-3 1e-3 1e-3" />
        </geometry>
      </visual>
    <collision>
      <geometry>
        <mesh filename="meshes/farm.stl" scale="1e-3 1e-3 1e-3" />
        </geometry>
      </collision>
    </link>
  <joint name="R_shoulder_y" type="fixed">
    <origin rpy="0 0 0" xyz="0 -0.255 0.45" />
    <parent link="trunk" />
    <child link="R_clav" />
    <axis xyz="0.0 1.0 0.0" />
    <limit effort="60" lower="-3.1416" upper="3.1416" velocity="0" />
    <dynamics damping="0" friction="0" />
    </joint>
  <link name="R_clav">
    <inertial>
      <origin rpy="0.0 0.0 0.0" xyz="0.0012122056 0.0015095858 -9.3677479e-05" />
      <mass value="1.1246895" />
      <inertia ixx="0.0017070766" ixy="2.3820729e-06" ixz="-6.7619904e-06" iyy="0.0010595629" iyz="3.2352008e-07" izz="0.001122517" />
      </inertial>
    <visual>
      <origin rpy="0 0 0" xyz="0 0 0" />
      <geometry>
        <mesh filename="meshes/clav.stl" scale="1e-3 1e-3 1e-3" />
        </geometry>
      </visual>
    <collision>
      <origin rpy="0 0 0" xyz="0 0 0" />
      <geometry>
        <mesh filename="meshes/clav.stl" scale="1e-3 1e-3 1e-3" />
        </geometry>
      </collision>
    </link>
  <joint name="R_shoulder_x" type="fixed">
    <origin rpy="0.0 0.0 0.0" xyz="0 0 0" />
    <parent link="R_clav" />
    <child link="R_scapula" />
    <axis xyz="1.0 0.0 0.0" />
    <limit effort="60" lower="-3.1416" upper="0" velocity="0" />
    <dynamics damping="0" friction="0" />
    </joint>
  <link name="R_scapula">
    <inertial>
      <origin rpy="0.0 0.0 0.0" xyz="0.0038106082 -0.0001642433 -0.095219061" />
      <mass value="0.65454544" />
      <inertia ixx="0.0011234347" ixy="-4.6391796e-06" ixz="-0.00021802428" iyy="0.0011878253" iyz="-1.8375484e-06" izz="0.00058824357" />
      </inertial>
    <visual>
      <geometry>
        <mesh filename="meshes/scap.stl" scale="1e-3 1e-3 1e-3" />
        </geometry>
      </visual>
    <collision>
      <geometry>
        <mesh filename="meshes/scap.stl" scale="1e-3 1e-3 1e-3" />
        </geometry>
      </collision>
    </link>
  <joint name="R_shoulder_z" type="fixed">
    <origin rpy="0.0 0.0 0.0" xyz="0 0 0" />
    <parent link="R_scapula" />
    <child link="R_uarm" />
    <axis xyz="0.0 0.0 1.0" />
    <limit effort="17" lower="-3.14" upper="3.14" velocity="0" />
    <dynamics damping="0" friction="0" />
    </joint>
  <link name="R_uarm">
    <inertial>
      <origin rpy="0.0 0.0 0.0" xyz="-0.0039088302 -0.00017072539 -0.22223086" />
      <mass value="0.58244405" />
      <inertia ixx="0.00083861306" ixy="9.1542325e-08" ixz="0" iyy="0.00067605212" iyz="2.7860944e-06" izz="0.0003615168" />
      </inertial>
    <visual>
      <geometry>
        <mesh filename="meshes/uarm.stl" scale="1e-3 1e-3 1e-3" />
        </geometry>
      </visual>
    <collision>
      <geometry>
        <mesh filename="meshes/uarm.stl" scale="1e-3 1e-3 1e-3" />
        </geometry>
      </collision>
    </link>
  <joint name="R_elbow_x" type="fixed">
    <origin rpy="0.0 0.0 0.0" xyz="0 0 -0.23" />
    <parent link="R_uarm" />
    <child link="R_farm" />
    <axis xyz="1.0 0 0.0" />
    <limit effort="17" lower="-1.9199" upper="1.9199" velocity="0" />
    <dynamics damping="0" friction="0" />
    </joint>
  <link name="R_farm">
    <inertial>
      <origin rpy="0.0 0.0 0.0" xyz="-0.0024082691 -0.00017091831 -0.14069589" />
      <mass value="0.66002606" />
      <inertia ixx="0.0016198862" ixy="-3.700055e-06" ixz="0.00013980511" iyy="0.0016516658" iyz="-2.349341e-06" izz="0.00054139396" />
      </inertial>
    <visual>
      <geometry>
        <mesh filename="meshes/farm.stl" scale="1e-3 1e-3 1e-3" />
        </geometry>
      </visual>
    <collision>
      <geometry>
        <mesh filename="meshes/farm.stl" scale="1e-3 1e-3 1e-3" />
        </geometry>
      </collision>
    </link>
  </robot>